Workbook

Sheet Original_Dataset
A1: store_id | B1: month | C1: region | D1: store_type | E1: marketing_spend | F1: footfall | G1: avg_discount_pct | H1: staff_count | I1: inventory_availability_pct | J1: competitor_distance_km | K1: holiday_flag | L1: customer_rating | M1: monthly_sales | N1: monthly_profit
A2: STR-1001 | B2: 45658 | C2: East | D2: Residential | E2: 70389.11 | F2: 8302 | G2: 0.042 | H2: 17 | I2: 75 | J2: 5.28 | K2: 1 | L2: 3.1 | M2: 658832.62 | N2: 84349.93
A3: STR-1001 | B3: 45689 | C3: East | D3: Residential | E3: 43827.89 | F3: 8487 | G3: 0.168 | H3: 23 | I3: 84.4 | J3: 4.31 | K3: 0 | L3: 2.8 | M3: 634436 | N3: 106130.54
A4: STR-1001 | B4: 45717 | C4: East | D4: Residential | E4: 59921.75 | F4: 9113 | G4: 0.133 | H4: 20 | I4: 88 | J4: 12 | K4: 0 | L4: 3.2 | M4: 678722.06 | N4: 101883.86
A5: STR-1001 | B5: 45748 | C5: East | D5: Residential | E5: 56856.63 | F5: 9431 | G5: 0.142 | H5: 23 | I5: 86.9 | J5: 4.97 | K5: 0 | L5: 3.4 | M5: 658920.3 | N5: 97910.37
A6: STR-1002 | B6: 45658 | C6: East | D6: High Street | E6: 48412.64 | F6: 9545 | G6: 0.231 | H6: 21 | I6: 97.6 | J6: 6.94 | K6: 1 | L6: 4.2 | M6: 741341.44 | N6: 119208.17
A7: STR-1002 | B7: 45689 | C7: East | D7: High Street | E7: 64811.21 | F7: 9792 | G7: 0.112 | H7: 20 | I7: 84.2 | J7: 2.88 | K7: 0 | L7: 4.2 | M7: 761835.34 | N7: 149602.23
A8: STR-1002 | B8: 45717 | C8: East | D8: High Street | E8: 46213.45 | F8: 10616 | G8: 0.122 | H8: 22 | I8: 85.2 | J8: 0.2 | K8: 1 | L8: 4.1 | M8: 806615.54 | N8: 131364.62
A9: STR-1002 | B9: 45748 | C9: East | D9: High Street | E9: 68148.52 | F9: 8567 | G9: 0.127 | H9: 23 | I9: 95.6 | J9: 0.8 | K9: 0 | L9: 3.9 | M9: 850164.26 | N9: 149262.75
A10: STR-1003 | B10: 45658 | C10: North | D10: Airport | E10: 71838.86 | F10: 10979 | G10: 0.215 | H10: 26 | I10: 88.6 | J10: 7.7 | K10: 1 | L10: 3.8 | M10: 930581.7 | N10: 136207.98
A11: STR-1003 | B11: 45689 | C11: North | D11: Airport | E11: 68133.44 | F11: 9459 | G11: 0.22 | H11: 21 | I11: 85 | J11: 1.91 | K11: 0 | L11: 4.2 | M11: 779010.94 | N11: 106328.09
A12: STR-1003 | B12: 45717 | C12: North | D12: Airport | E12: 34285.21 | F12: 9172 | G12: 0.213 | H12: 22 | I12: 88.3 | J12: 10.46 | K12: 1 | L12: 3.8 | M12: 723060.76 | N12: 123131.24
A13: STR-1003 | B13: 45748 | C13: North | D13: Airport | E13: 67979.88 | F13: 11230 | G13: 0.002 | H13: 28 | I13: 85.3 | J13: 7.16 | K13: 0 | L13: 3.8 | M13: 910791.94 | N13: 158891.28
... A34: STR-1009 | B34: 45658 | C34: North | D34: Residential | E34: 54597.83 | F34: 9429 | G34: 0.188 | H34: 21 | I34: 83.3 | J34: 11.71 | K34: 0 | L34: 4.2 | M34: 641865.03 | N34: 81342.58
A35: STR-1009 | B35: 45689 | C35: North | D35: Residential | E35: 73771.91 | F35: 11695 | G35: 0.07 | H35: 25 | I35: 84.7 | J35: 0.62 | K35: 0 | M35: 799477.76 | N35: 164974.41
A36: STR-1009 | B36: 45717 | C36: North | D36: Residential | E36: 74413.88 | F36: 9449 | G36: 0.039 | H36: 23 | I36: 92.1 | J36: 2.12 | K36: 0 | L36: 3.5 | M36: 798952.17 | N36: 161499.04
A37: STR-1009 | B37: 45748 | C37: North | D37: Residential | E37: 52483.77 | F37: 10453 | G37: 0.247 | H37: 25 | I37: 99 | J37: 6.31 | K37: 0 | L37: 3.6 | M37: 800979.78 | N37: 149242.27
A38: STR-1010 | B38: 45658 | C38: North | D38: Mall | E38: 75269.87 | F38: 8838 | G38: 0.092 | H38: 21 | I38: 83.1 | J38: 9.56 | K38: 1 | L38: 4.2 | M38: 820593.93 | N38: 115860.06
A39: STR-1010 | B39: 45689 | C39: North | D39: Mall | E39: 61245.41 | F39: 8156 | G39: 0.156 | H39: 19 | I39: 92.9 | J39: 9.05 | K39: 0 | L39: 3.8 | M39: 718330.53 | N39: 93247.9
A40: STR-1010 | B40: 45717 | C40: North | D40: Mall | E40: 93381.26 | F40: 7562 | G40: 0.198 | H40: 19 | I40: 82.9 | J40: 5.05 | K40: 0 | L40: 4 | M40: 736633.4 | N40: 115654.66
A41: STR-1010 | B41: 45748 | C41: North | D41: Mall | E41: 65012.19 | F41: 9598 | G41: 0.085 | H41: 24 | I41: 98.3 | J41: 0.89 | K41: 0 | L41: 3.8 | M41: 828623.85 | N41: 167320.52
A42: STR-1011 | B42: 45658 | C42: East | D42: Mall | E42: 40462.94 | F42: 3660 | G42: 0.218 | H42: 11 | I42: 95.2 | J42: 5.57 | K42: 0 | L42: 4.4 | M42: 592195.85 | N42: 92291.56
A43: STR-1011 | B43: 45689 | C43: East | D43: Mall | E43: 46123.88 | F43: 3227 | G43: 0.143 | H43: 10 | I43: 75.4 | J43: 1.06 | K43: 0 | L43: 4.4 | M43: 532644.46 | N43: 60681.32
A44: STR-1011 | B44: 45717 | C44: East | D44: Mall | E44: 68077.54 | F44: 3360 | G44: 0.128 | H44: 14 | I44: 88.2 | J44: 1.24 | K44: 1 | L44: 4 | M44: 657429.18 | N44: 88919.74
A45: STR-1011 | B45: 45748 | C45: East | D45: Mall | E45: 64882.14 | F45: 3642 | G45: 0.019 | H45: 13 | I45: 87.8 | J45: 4.52 | K45: 0 | L45: 4.2 | M45: 605178 | N45: 106958.74
A46: STR-1012 | B46: 45658 | C46: West | D46: Residential | E46: 138855.51 | F46: 5145 | G46: 0.06 | H46: 17 | I46: 88.2 | J46: 9.58 | K46: 0 | L46: 3.2 | M46: 595467.6 | N46: 104276.46
A47: STR-1012 | B47: 45689 | C47: West | D47: Residential | E47: 63630.21 | F47: 4460 | G47: 0.235 | H47: 14 | I47: 98.6 | J47: 5.52 | K47: 0 | L47: 3.5 | M47: 599603.4 | N47: 112685.12
... A72: STR-1018 | B72: 45717 | C72: East | D72: High Street | E72: 60571.82 | F72: 3193 | G72: 0.197 | H72: 7 | I72: 99 | J72: 1.43 | K72: 0 | L72: 3.2 | M72: 605023.87 | N72: 98545.81
A73: STR-1018 | B73: 45748 | C73: East | D73: High Street | E73: 55081.16 | F73: 5485 | G73: 0.036 | H73: 12 | I73: 88 | K73: 0 | L73: 3.5 | M73: 674774.09 | N73: 141917.59
A74: STR-1019 | B74: 45658 | C74: East | D74: Residential | E74: 46201.46 | F74: 5918 | G74: 0.277 | H74: 13 | I74: 78.8 | J74: 4.91 | K74: 0 | L74: 4.5 | M74: 616069.41 | N74: 54453.99
A75: STR-1019 | B75: 45689 | C75: East | D75: Residential | E75: 53762.92 | F75: 6821 | G75: 0.066 | H75: 19 | I75: 94.6 | J75: 7.03 | K75: 0 | L75: 4.4 | M75: 630829.94 | N75: 117090.02
A76: STR-1019 | B76: 45717 | C76: East | D76: Residential | E76: 70144.78 | F76: 6806 | G76: 0.178 | H76: 20 | I76: 93.1 | J76: 0.28 | K76: 1 | L76: 4.3 | M76: 788087.68 | N76: 116803.42
A77: STR-1019 | B77: 45748 | C77: East | D77: Residential | E77: 58749.63 | F77: 8252 | G77: 0.203 | H77: 20 | I77: 85.2 | J77: 3.61 | K77: 0 | L77: 4.5 | M77: 680840.36 | N77: 68007.68
A78: STR-1020 | B78: 45658 | C78: South | D78: High Street | E78: 56973.18 | F78: 6662 | G78: 0.1 | H78: 15 | I78: 77.7 | J78: 7.52 | K78: 1 | L78: 3.2 | M78: 643657.47 | N78: 87022.45
A79: STR-1020 | B79: 45689 | C79: South | D79: High Street | E79: 54872.82 | F79: 5962 | G79: 0.064 | H79: 12 | I79: 85.4 | J79: 2.58 | K79: 0 | L79: 2.9 | M79: 691112.6 | N79: 109212.83
A80: STR-1020 | B80: 45717 | C80: South | D80: High Street | E80: 80562.81 | F80: 7470 | G80: 0.172 | H80: 16 | I80: 83.5 | J80: 2.29 | K80: 0 | L80: 3.3 | M80: 776922.17 | N80: 150701.93
A81: STR-1020 | B81: 45748 | C81: South | D81: High Street | E81: 77999.9 | F81: 5974 | G81: 0.252 | H81: 14 | I81: 81.3 | J81: 2.39 | K81: 0 | L81: 3.2 | M81: 636561.34 | N81: 93861.06
A82: STR-1021 | B82: 45658 | C82: West | D82: Mall | E82: 60881.01 | F82: 5410 | G82: 0.179 | H82: 15 | I82: 83.9 | J82: 5.24 | K82: 0 | L82: 4.6 | M82: 621369.58 | N82: 85493.64
A83: STR-1021 | B83: 45689 | C83: West | D83: Mall | E83: 60628.38 | F83: 4451 | G83: 0.095 | H83: 10 | I83: 89.6 | J83: 3.17 | K83: 0 | L83: 4.6 | M83: 682208.01 | N83: 110318.84
A84: STR-1021 | B84: 45717 | C84: West | D84: Mall | E84: 72731.14 | F84: 4644 | G84: 0.084 | H84: 15 | I84: 87.1 | J84: 2.66 | K84: 0 | L84: 4.6 | M84: 727241.86 | N84: 155810.3
...

Sheet Cleaned_Prepared_Data
A1: store_id | B1: month | C1: region | D1: store_type | E1: marketing_spend | F1: footfall | G1: avg_discount_pct | H1: staff_count | I1: inventory_availability_pct | J1: competitor_distance_km | K1: holiday_flag | L1: customer_rating | M1: monthly_sales | N1: monthly_profit | O1: month_date | P1: month_year | Q1: sales_per_footfall | R1: profit_margin | S1: data_check
A2: STR-1001 | B2: 45658 | C2: East | D2: Residential | E2: 70389.11 | F2: 8302 | G2: 0.042 | H2: 17 | I2: 75 | J2: 5.28 | K2: 1 | L2: 3.1 | M2: 658832.62 | N2: 84349.93 | O2: =B2 -> 45658 | P2: =TEXT(O2,"yyyy-mm") -> 2025-01 | Q2: =IFERROR(M2/F2,"") -> 79.358302 | R2: =IFERROR(N2/M2,"") -> 0.12802938 | S2: =IF(OR(M2="",E2="",F2="",I2=""),"Check","OK") -> OK
A3: STR-1001 | B3: 45689 | C3: East | D3: Residential | E3: 43827.89 | F3: 8487 | G3: 0.168 | H3: 23 | I3: 84.4 | J3: 4.31 | K3: 0 | L3: 2.8 | M3: 634436 | N3: 106130.54 | O3: =B3 -> 45689 | P3: =TEXT(O3,"yyyy-mm") -> 2025-02 | Q3: =IFERROR(M3/F3,"") -> 74.753859 | R3: =IFERROR(N3/M3,"") -> 0.16728329 | S3: =IF(OR(M3="",E3="",F3="",I3=""),"Check","OK") -> OK
A4: STR-1001 | B4: 45717 | C4: East | D4: Residential | E4: 59921.75 | F4: 9113 | G4: 0.133 | H4: 20 | I4: 88 | J4: 12 | K4: 0 | L4: 3.2 | M4: 678722.06 | N4: 101883.86 | O4: =B4 -> 45717 | P4: =TEXT(O4,"yyyy-mm") -> 2025-03 | Q4: =IFERROR(M4/F4,"") -> 74.478444 | R4: =IFERROR(N4/M4,"") -> 0.15011131 | S4: =IF(OR(M4="",E4="",F4="",I4=""),"Check","OK") -> OK
A5: STR-1001 | B5: 45748 | C5: East | D5: Residential | E5: 56856.63 | F5: 9431 | G5: 0.142 | H5: 23 | I5: 86.9 | J5: 4.97 | K5: 0 | L5: 3.4 | M5: 658920.3 | N5: 97910.37 | O5: =B5 -> 45748 | P5: =TEXT(O5,"yyyy-mm") -> 2025-04 | Q5: =IFERROR(M5/F5,"") -> 69.86749 | R5: =IFERROR(N5/M5,"") -> 0.14859213 | S5: =IF(OR(M5="",E5="",F5="",I5=""),"Check","OK") -> OK
A6: STR-1002 | B6: 45658 | C6: East | D6: High Street | E6: 48412.64 | F6: 9545 | G6: 0.231 | H6: 21 | I6: 97.6 | J6: 6.94 | K6: 1 | L6: 4.2 | M6: 741341.44 | N6: 119208.17 | O6: =B6 -> 45658 | P6: =TEXT(O6,"yyyy-mm") -> 2025-01 | Q6: =IFERROR(M6/F6,"") -> 77.66804 | R6: =IFERROR(N6/M6,"") -> 0.16080063 | S6: =IF(OR(M6="",E6="",F6="",I6=""),"Check","OK") -> OK
A7: STR-1002 | B7: 45689 | C7: East | D7: High Street | E7: 64811.21 | F7: 9792 | G7: 0.112 | H7: 20 | I7: 84.2 | J7: 2.88 | K7: 0 | L7: 4.2 | M7: 761835.34 | N7: 149602.23 | O7: =B7 -> 45689 | P7: =TEXT(O7,"yyyy-mm") -> 2025-02 | Q7: =IFERROR(M7/F7,"") -> 77.801812 | R7: =IFERROR(N7/M7,"") -> 0.19637082 | S7: =IF(OR(M7="",E7="",F7="",I7=""),"Check","OK") -> OK
A8: STR-1002 | B8: 45717 | C8: East | D8: High Street | E8: 46213.45 | F8: 10616 | G8: 0.122 | H8: 22 | I8: 85.2 | J8: 0.2 | K8: 1 | L8: 4.1 | M8: 806615.54 | N8: 131364.62 | O8: =B8 -> 45717 | P8: =TEXT(O8,"yyyy-mm") -> 2025-03 | Q8: =IFERROR(M8/F8,"") -> 75.981117 | R8: =IFERROR(N8/M8,"") -> 0.16285902 | S8: =IF(OR(M8="",E8="",F8="",I8=""),"Check","OK") -> OK
A9: STR-1002 | B9: 45748 | C9: East | D9: High Street | E9: 68148.52 | F9: 8567 | G9: 0.127 | H9: 23 | I9: 95.6 | J9: 0.8 | K9: 0 | L9: 3.9 | M9: 850164.26 | N9: 149262.75 | O9: =B9 -> 45748 | P9: =TEXT(O9,"yyyy-mm") -> 2025-04 | Q9: =IFERROR(M9/F9,"") -> 99.237103 | R9: =IFERROR(N9/M9,"") -> 0.17556931 | S9: =IF(OR(M9="",E9="",F9="",I9=""),"Check","OK") -> OK
A10: STR-1003 | B10: 45658 | C10: North | D10: Airport | E10: 71838.86 | F10: 10979 | G10: 0.215 | H10: 26 | I10: 88.6 | J10: 7.7 | K10: 1 | L10: 3.8 | M10: 930581.7 | N10: 136207.98 | O10: =B10 -> 45658 | P10: =TEXT(O10,"yyyy-mm") -> 2025-01 | Q10: =IFERROR(M10/F10,"") -> 84.760151 | R10: =IFERROR(N10/M10,"") -> 0.14636864 | S10: =IF(OR(M10="",E10="",F10="",I10=""),"Check","OK") -> OK
A11: STR-1003 | B11: 45689 | C11: North | D11: Airport | E11: 68133.44 | F11: 9459 | G11: 0.22 | H11: 21 | I11: 85 | J11: 1.91 | K11: 0 | L11: 4.2 | M11: 779010.94 | N11: 106328.09 | O11: =B11 -> 45689 | P11: =TEXT(O11,"yyyy-mm") -> 2025-02 | Q11: =IFERROR(M11/F11,"") -> 82.356585 | R11: =IFERROR(N11/M11,"") -> 0.13649114 | S11: =IF(OR(M11="",E11="",F11="",I11=""),"Check","OK") -> OK
A12: STR-1003 | B12: 45717 | C12: North | D12: Airport | E12: 34285.21 | F12: 9172 | G12: 0.213 | H12: 22 | I12: 88.3 | J12: 10.46 | K12: 1 | L12: 3.8 | M12: 723060.76 | N12: 123131.24 | O12: =B12 -> 45717 | P12: =TEXT(O12,"yyyy-mm") -> 2025-03 | Q12: =IFERROR(M12/F12,"") -> 78.833489 | R12: =IFERROR(N12/M12,"") -> 0.17029169 | S12: =IF(OR(M12="",E12="",F12="",I12=""),"Check","OK") -> OK
A13: STR-1003 | B13: 45748 | C13: North | D13: Airport | E13: 67979.88 | F13: 11230 | G13: 0.002 | H13: 28 | I13: 85.3 | J13: 7.16 | K13: 0 | L13: 3.8 | M13: 910791.94 | N13: 158891.28 | O13: =B13 -> 45748 | P13: =TEXT(O13,"yyyy-mm") -> 2025-04 | Q13: =IFERROR(M13/F13,"") -> 81.103467 | R13: =IFERROR(N13/M13,"") -> 0.17445398 | S13: =IF(OR(M13="",E13="",F13="",I13=""),"Check","OK") -> OK
... A34: STR-1009 | B34: 45658 | C34: North | D34: Residential | E34: 54597.83 | F34: 9429 | G34: 0.188 | H34: 21 | I34: 83.3 | J34: 11.71 | K34: 0 | L34: 4.2 | M34: 641865.03 | N34: 81342.58 | O34: =B34 -> 45658 | P34: =TEXT(O34,"yyyy-mm") -> 2025-01 | Q34: =IFERROR(M34/F34,"") -> 68.0735 | R34: =IFERROR(N34/M34,"") -> 0.12672848 | S34: =IF(OR(M34="",E34="",F34="",I34=""),"Check","OK") -> OK
A35: STR-1009 | B35: 45689 | C35: North | D35: Residential | E35: 73771.91 | F35: 11695 | G35: 0.07 | H35: 25 | I35: 84.7 | J35: 0.62 | K35: 0 | M35: 799477.76 | N35: 164974.41 | O35: =B35 -> 45689 | P35: =TEXT(O35,"yyyy-mm") -> 2025-02 | Q35: =IFERROR(M35/F35,"") -> 68.360646 | R35: =IFERROR(N35/M35,"") -> 0.20635272 | S35: =IF(OR(M35="",E35="",F35="",I35=""),"Check","OK") -> OK
A36: STR-1009 | B36: 45717 | C36: North | D36: Residential | E36: 74413.88 | F36: 9449 | G36: 0.039 | H36: 23 | I36: 92.1 | J36: 2.12 | K36: 0 | L36: 3.5 | M36: 798952.17 | N36: 161499.04 | O36: =B36 -> 45717 | P36: =TEXT(O36,"yyyy-mm") -> 2025-03 | Q36: =IFERROR(M36/F36,"") -> 84.554151 | R36: =IFERROR(N36/M36,"") -> 0.20213856 | S36: =IF(OR(M36="",E36="",F36="",I36=""),"Check","OK") -> OK
A37: STR-1009 | B37: 45748 | C37: North | D37: Residential | E37: 52483.77 | F37: 10453 | G37: 0.247 | H37: 25 | I37: 99 | J37: 6.31 | K37: 0 | L37: 3.6 | M37: 800979.78 | N37: 149242.27 | O37: =B37 -> 45748 | P37: =TEXT(O37,"yyyy-mm") -> 2025-04 | Q37: =IFERROR(M37/F37,"") -> 76.626785 | R37: =IFERROR(N37/M37,"") -> 0.18632464 | S37: =IF(OR(M37="",E37="",F37="",I37=""),"Check","OK") -> OK
A38: STR-1010 | B38: 45658 | C38: North | D38: Mall | E38: 75269.87 | F38: 8838 | G38: 0.092 | H38: 21 | I38: 83.1 | J38: 9.56 | K38: 1 | L38: 4.2 | M38: 820593.93 | N38: 115860.06 | O38: =B38 -> 45658 | P38: =TEXT(O38,"yyyy-mm") -> 2025-01 | Q38: =IFERROR(M38/F38,"") -> 92.848374 | R38: =IFERROR(N38/M38,"") -> 0.14119049 | S38: =IF(OR(M38="",E38="",F38="",I38=""),"Check","OK") -> OK
A39: STR-1010 | B39: 45689 | C39: North | D39: Mall | E39: 61245.41 | F39: 8156 | G39: 0.156 | H39: 19 | I39: 92.9 | J39: 9.05 | K39: 0 | L39: 3.8 | M39: 718330.53 | N39: 93247.9 | O39: =B39 -> 45689 | P39: =TEXT(O39,"yyyy-mm") -> 2025-02 | Q39: =IFERROR(M39/F39,"") -> 88.073876 | R39: =IFERROR(N39/M39,"") -> 0.12981197 | S39: =IF(OR(M39="",E39="",F39="",I39=""),"Check","OK") -> OK
A40: STR-1010 | B40: 45717 | C40: North | D40: Mall | E40: 93381.26 | F40: 7562 | G40: 0.198 | H40: 19 | I40: 82.9 | J40: 5.05 | K40: 0 | L40: 4 | M40: 736633.4 | N40: 115654.66 | O40: =B40 -> 45717 | P40: =TEXT(O40,"yyyy-mm") -> 2025-03 | Q40: =IFERROR(M40/F40,"") -> 97.41251 | R40: =IFERROR(N40/M40,"") -> 0.15700437 | S40: =IF(OR(M40="",E40="",F40="",I40=""),"Check","OK") -> OK
A41: STR-1010 | B41: 45748 | C41: North | D41: Mall | E41: 65012.19 | F41: 9598 | G41: 0.085 | H41: 24 | I41: 98.3 | J41: 0.89 | K41: 0 | L41: 3.8 | M41: 828623.85 | N41: 167320.52 | O41: =B41 -> 45748 | P41: =TEXT(O41,"yyyy-mm") -> 2025-04 | Q41: =IFERROR(M41/F41,"") -> 86.33297 | R41: =IFERROR(N41/M41,"") -> 0.20192578 | S41: =IF(OR(M41="",E41="",F41="",I41=""),"Check","OK") -> OK
A42: STR-1011 | B42: 45658 | C42: East | D42: Mall | E42: 40462.94 | F42: 3660 | G42: 0.218 | H42: 11 | I42: 95.2 | J42: 5.57 | K42: 0 | L42: 4.4 | M42: 592195.85 | N42: 92291.56 | O42: =B42 -> 45658 | P42: =TEXT(O42,"yyyy-mm") -> 2025-01 | Q42: =IFERROR(M42/F42,"") -> 161.80214 | R42: =IFERROR(N42/M42,"") -> 0.15584635 | S42: =IF(OR(M42="",E42="",F42="",I42=""),"Check","OK") -> OK
A43: STR-1011 | B43: 45689 | C43: East | D43: Mall | E43: 46123.88 | F43: 3227 | G43: 0.143 | H43: 10 | I43: 75.4 | J43: 1.06 | K43: 0 | L43: 4.4 | M43: 532644.46 | N43: 60681.32 | O43: =B43 -> 45689 | P43: =TEXT(O43,"yyyy-mm") -> 2025-02 | Q43: =IFERROR(M43/F43,"") -> 165.05871 | R43: =IFERROR(N43/M43,"") -> 0.11392462 | S43: =IF(OR(M43="",E43="",F43="",I43=""),"Check","OK") -> OK
A44: STR-1011 | B44: 45717 | C44: East | D44: Mall | E44: 68077.54 | F44: 3360 | G44: 0.128 | H44: 14 | I44: 88.2 | J44: 1.24 | K44: 1 | L44: 4 | M44: 657429.18 | N44: 88919.74 | O44: =B44 -> 45717 | P44: =TEXT(O44,"yyyy-mm") -> 2025-03 | Q44: =IFERROR(M44/F44,"") -> 195.66345 | R44: =IFERROR(N44/M44,"") -> 0.13525372 | S44: =IF(OR(M44="",E44="",F44="",I44=""),"Check","OK") -> OK
A45: STR-1011 | B45: 45748 | C45: East | D45: Mall | E45: 64882.14 | F45: 3642 | G45: 0.019 | H45: 13 | I45: 87.8 | J45: 4.52 | K45: 0 | L45: 4.2 | M45: 605178 | N45: 106958.74 | O45: =B45 -> 45748 | P45: =TEXT(O45,"yyyy-mm") -> 2025-04 | Q45: =IFERROR(M45/F45,"") -> 166.16639 | R45: =IFERROR(N45/M45,"") -> 0.17673931 | S45: =IF(OR(M45="",E45="",F45="",I45=""),"Check","OK") -> OK
A46: STR-1012 | B46: 45658 | C46: West | D46: Residential | E46: 138855.51 | F46: 5145 | G46: 0.06 | H46: 17 | I46: 88.2 | J46: 9.58 | K46: 0 | L46: 3.2 | M46: 595467.6 | N46: 104276.46 | O46: =B46 -> 45658 | P46: =TEXT(O46,"yyyy-mm") -> 2025-01 | Q46: =IFERROR(M46/F46,"") -> 115.73714 | R46: =IFERROR(N46/M46,"") -> 0.17511693 | S46: =IF(OR(M46="",E46="",F46="",I46=""),"Check","OK") -> OK
A47: STR-1012 | B47: 45689 | C47: West | D47: Residential | E47: 63630.21 | F47: 4460 | G47: 0.235 | H47: 14 | I47: 98.6 | J47: 5.52 | K47: 0 | L47: 3.5 | M47: 599603.4 | N47: 112685.12 | O47: =B47 -> 45689 | P47: =TEXT(O47,"yyyy-mm") -> 2025-02 | Q47: =IFERROR(M47/F47,"") -> 134.44022 | R47: =IFERROR(N47/M47,"") -> 0.18793276 | S47: =IF(OR(M47="",E47="",F47="",I47=""),"Check","OK") -> OK
... A72: STR-1018 | B72: 45717 | C72: East | D72: High Street | E72: 60571.82 | F72: 3193 | G72: 0.197 | H72: 7 | I72: 99 | J72: 1.43 | K72: 0 | L72: 3.2 | M72: 605023.87 | N72: 98545.81 | O72: =B72 -> 45717 | P72: =TEXT(O72,"yyyy-mm") -> 2025-03 | Q72: =IFERROR(M72/F72,"") -> 189.48446 | R72: =IFERROR(N72/M72,"") -> 0.16287921 | S72: =IF(OR(M72="",E72="",F72="",I72=""),"Check","OK") -> OK
A73: STR-1018 | B73: 45748 | C73: East | D73: High Street | E73: 55081.16 | F73: 5485 | G73: 0.036 | H73: 12 | I73: 88 | K73: 0 | L73: 3.5 | M73: 674774.09 | N73: 141917.59 | O73: =B73 -> 45748 | P73: =TEXT(O73,"yyyy-mm") -> 2025-04 | Q73: =IFERROR(M73/F73,"") -> 123.02171 | R73: =IFERROR(N73/M73,"") -> 0.21031867 | S73: =IF(OR(M73="",E73="",F73="",I73=""),"Check","OK") -> OK
A74: STR-1019 | B74: 45658 | C74: East | D74: Residential | E74: 46201.46 | F74: 5918 | G74: 0.277 | H74: 13 | I74: 78.8 | J74: 4.91 | K74: 0 | L74: 4.5 | M74: 616069.41 | N74: 54453.99 | O74: =B74 -> 45658 | P74: =TEXT(O74,"yyyy-mm") -> 2025-01 | Q74: =IFERROR(M74/F74,"") -> 104.10095 | R74: =IFERROR(N74/M74,"") -> 0.088389375 | S74: =IF(OR(M74="",E74="",F74="",I74=""),"Check","OK") -> OK
A75: STR-1019 | B75: 45689 | C75: East | D75: Residential | E75: 53762.92 | F75: 6821 | G75: 0.066 | H75: 19 | I75: 94.6 | J75: 7.03 | K75: 0 | L75: 4.4 | M75: 630829.94 | N75: 117090.02 | O75: =B75 -> 45689 | P75: =TEXT(O75,"yyyy-mm") -> 2025-02 | Q75: =IFERROR(M75/F75,"") -> 92.483498 | R75: =IFERROR(N75/M75,"") -> 0.18561265 | S75: =IF(OR(M75="",E75="",F75="",I75=""),"Check","OK") -> OK
A76: STR-1019 | B76: 45717 | C76: East | D76: Residential | E76: 70144.78 | F76: 6806 | G76: 0.178 | H76: 20 | I76: 93.1 | J76: 0.28 | K76: 1 | L76: 4.3 | M76: 788087.68 | N76: 116803.42 | O76: =B76 -> 45717 | P76: =TEXT(O76,"yyyy-mm") -> 2025-03 | Q76: =IFERROR(M76/F76,"") -> 115.79308 | R76: =IFERROR(N76/M76,"") -> 0.1482112 | S76: =IF(OR(M76="",E76="",F76="",I76=""),"Check","OK") -> OK
A77: STR-1019 | B77: 45748 | C77: East | D77: Residential | E77: 58749.63 | F77: 8252 | G77: 0.203 | H77: 20 | I77: 85.2 | J77: 3.61 | K77: 0 | L77: 4.5 | M77: 680840.36 | N77: 68007.68 | O77: =B77 -> 45748 | P77: =TEXT(O77,"yyyy-mm") -> 2025-04 | Q77: =IFERROR(M77/F77,"") -> 82.506103 | R77: =IFERROR(N77/M77,"") -> 0.09988785 | S77: =IF(OR(M77="",E77="",F77="",I77=""),"Check","OK") -> OK
A78: STR-1020 | B78: 45658 | C78: South | D78: High Street | E78: 56973.18 | F78: 6662 | G78: 0.1 | H78: 15 | I78: 77.7 | J78: 7.52 | K78: 1 | L78: 3.2 | M78: 643657.47 | N78: 87022.45 | O78: =B78 -> 45658 | P78: =TEXT(O78,"yyyy-mm") -> 2025-01 | Q78: =IFERROR(M78/F78,"") -> 96.616252 | R78: =IFERROR(N78/M78,"") -> 0.13519994 | S78: =IF(OR(M78="",E78="",F78="",I78=""),"Check","OK") -> OK
A79: STR-1020 | B79: 45689 | C79: South | D79: High Street | E79: 54872.82 | F79: 5962 | G79: 0.064 | H79: 12 | I79: 85.4 | J79: 2.58 | K79: 0 | L79: 2.9 | M79: 691112.6 | N79: 109212.83 | O79: =B79 -> 45689 | P79: =TEXT(O79,"yyyy-mm") -> 2025-02 | Q79: =IFERROR(M79/F79,"") -> 115.91959 | R79: =IFERROR(N79/M79,"") -> 0.15802465 | S79: =IF(OR(M79="",E79="",F79="",I79=""),"Check","OK") -> OK
A80: STR-1020 | B80: 45717 | C80: South | D80: High Street | E80: 80562.81 | F80: 7470 | G80: 0.172 | H80: 16 | I80: 83.5 | J80: 2.29 | K80: 0 | L80: 3.3 | M80: 776922.17 | N80: 150701.93 | O80: =B80 -> 45717 | P80: =TEXT(O80,"yyyy-mm") -> 2025-03 | Q80: =IFERROR(M80/F80,"") -> 104.00565 | R80: =IFERROR(N80/M80,"") -> 0.19397301 | S80: =IF(OR(M80="",E80="",F80="",I80=""),"Check","OK") -> OK
A81: STR-1020 | B81: 45748 | C81: South | D81: High Street | E81: 77999.9 | F81: 5974 | G81: 0.252 | H81: 14 | I81: 81.3 | J81: 2.39 | K81: 0 | L81: 3.2 | M81: 636561.34 | N81: 93861.06 | O81: =B81 -> 45748 | P81: =TEXT(O81,"yyyy-mm") -> 2025-04 | Q81: =IFERROR(M81/F81,"") -> 106.5553 | R81: =IFERROR(N81/M81,"") -> 0.14745014 | S81: =IF(OR(M81="",E81="",F81="",I81=""),"Check","OK") -> OK
A82: STR-1021 | B82: 45658 | C82: West | D82: Mall | E82: 60881.01 | F82: 5410 | G82: 0.179 | H82: 15 | I82: 83.9 | J82: 5.24 | K82: 0 | L82: 4.6 | M82: 621369.58 | N82: 85493.64 | O82: =B82 -> 45658 | P82: =TEXT(O82,"yyyy-mm") -> 2025-01 | Q82: =IFERROR(M82/F82,"") -> 114.85574 | R82: =IFERROR(N82/M82,"") -> 0.13758903 | S82: =IF(OR(M82="",E82="",F82="",I82=""),"Check","OK") -> OK
A83: STR-1021 | B83: 45689 | C83: West | D83: Mall | E83: 60628.38 | F83: 4451 | G83: 0.095 | H83: 10 | I83: 89.6 | J83: 3.17 | K83: 0 | L83: 4.6 | M83: 682208.01 | N83: 110318.84 | O83: =B83 -> 45689 | P83: =TEXT(O83,"yyyy-mm") -> 2025-02 | Q83: =IFERROR(M83/F83,"") -> 153.27073 | R83: =IFERROR(N83/M83,"") -> 0.16170851 | S83: =IF(OR(M83="",E83="",F83="",I83=""),"Check","OK") -> OK
A84: STR-1021 | B84: 45717 | C84: West | D84: Mall | E84: 72731.14 | F84: 4644 | G84: 0.084 | H84: 15 | I84: 87.1 | J84: 2.66 | K84: 0 | L84: 4.6 | M84: 727241.86 | N84: 155810.3 | O84: =B84 -> 45717 | P84: =TEXT(O84,"yyyy-mm") -> 2025-03 | Q84: =IFERROR(M84/F84,"") -> 156.59816 | R84: =IFERROR(N84/M84,"") -> 0.21424826 | S84: =IF(OR(M84="",E84="",F84="",I84=""),"Check","OK") -> OK
...

Sheet Dummy_Variables
A1: store_id | B1: month_year | C1: region | D1: store_type | E1: monthly_sales | F1: marketing_spend | G1: footfall | H1: avg_discount_pct | I1: staff_count | J1: inventory_availability_pct | K1: holiday_flag | L1: customer_rating | M1: store_type_airport | N1: store_type_high_street | O1: store_type_mall
A2: =Cleaned_Prepared_Data!A2 -> STR-1001 | B2: =Cleaned_Prepared_Data!P2 -> 2025-01 | C2: =Cleaned_Prepared_Data!C2 -> East | D2: =Cleaned_Prepared_Data!D2 -> Residential | E2: =Cleaned_Prepared_Data!M2 -> 658832.62 | F2: =Cleaned_Prepared_Data!E2 -> 70389.11 | G2: =Cleaned_Prepared_Data!F2 -> 8302 | H2: =Cleaned_Prepared_Data!G2 -> 0.042 | I2: =Cleaned_Prepared_Data!H2 -> 17 | J2: =Cleaned_Prepared_Data!I2 -> 75 | K2: =Cleaned_Prepared_Data!K2 -> 1 | L2: =Cleaned_Prepared_Data!L2 -> 3.1 | M2: =IF($D2="Airport",1,0) -> 0 | N2: =IF($D2="High Street",1,0) -> 0 | O2: =IF($D2="Mall",1,0) -> 0
A3: =Cleaned_Prepared_Data!A3 -> STR-1001 | B3: =Cleaned_Prepared_Data!P3 -> 2025-02 | C3: =Cleaned_Prepared_Data!C3 -> East | D3: =Cleaned_Prepared_Data!D3 -> Residential | E3: =Cleaned_Prepared_Data!M3 -> 634436 | F3: =Cleaned_Prepared_Data!E3 -> 43827.89 | G3: =Cleaned_Prepared_Data!F3 -> 8487 | H3: =Cleaned_Prepared_Data!G3 -> 0.168 | I3: =Cleaned_Prepared_Data!H3 -> 23 | J3: =Cleaned_Prepared_Data!I3 -> 84.4 | K3: =Cleaned_Prepared_Data!K3 -> 0 | L3: =Cleaned_Prepared_Data!L3 -> 2.8 | M3: =IF($D3="Airport",1,0) -> 0 | N3: =IF($D3="High Street",1,0) -> 0 | O3: =IF($D3="Mall",1,0) -> 0
A4: =Cleaned_Prepared_Data!A4 -> STR-1001 | B4: =Cleaned_Prepared_Data!P4 -> 2025-03 | C4: =Cleaned_Prepared_Data!C4 -> East | D4: =Cleaned_Prepared_Data!D4 -> Residential | E4: =Cleaned_Prepared_Data!M4 -> 678722.06 | F4: =Cleaned_Prepared_Data!E4 -> 59921.75 | G4: =Cleaned_Prepared_Data!F4 -> 9113 | H4: =Cleaned_Prepared_Data!G4 -> 0.133 | I4: =Cleaned_Prepared_Data!H4 -> 20 | J4: =Cleaned_Prepared_Data!I4 -> 88 | K4: =Cleaned_Prepared_Data!K4 -> 0 | L4: =Cleaned_Prepared_Data!L4 -> 3.2 | M4: =IF($D4="Airport",1,0) -> 0 | N4: =IF($D4="High Street",1,0) -> 0 | O4: =IF($D4="Mall",1,0) -> 0
A5: =Cleaned_Prepared_Data!A5 -> STR-1001 | B5: =Cleaned_Prepared_Data!P5 -> 2025-04 | C5: =Cleaned_Prepared_Data!C5 -> East | D5: =Cleaned_Prepared_Data!D5 -> Residential | E5: =Cleaned_Prepared_Data!M5 -> 658920.3 | F5: =Cleaned_Prepared_Data!E5 -> 56856.63 | G5: =Cleaned_Prepared_Data!F5 -> 9431 | H5: =Cleaned_Prepared_Data!G5 -> 0.142 | I5: =Cleaned_Prepared_Data!H5 -> 23 | J5: =Cleaned_Prepared_Data!I5 -> 86.9 | K5: =Cleaned_Prepared_Data!K5 -> 0 | L5: =Cleaned_Prepared_Data!L5 -> 3.4 | M5: =IF($D5="Airport",1,0) -> 0 | N5: =IF($D5="High Street",1,0) -> 0 | O5: =IF($D5="Mall",1,0) -> 0
A6: =Cleaned_Prepared_Data!A6 -> STR-1002 | B6: =Cleaned_Prepared_Data!P6 -> 2025-01 | C6: =Cleaned_Prepared_Data!C6 -> East | D6: =Cleaned_Prepared_Data!D6 -> High Street | E6: =Cleaned_Prepared_Data!M6 -> 741341.44 | F6: =Cleaned_Prepared_Data!E6 -> 48412.64 | G6: =Cleaned_Prepared_Data!F6 -> 9545 | H6: =Cleaned_Prepared_Data!G6 -> 0.231 | I6: =Cleaned_Prepared_Data!H6 -> 21 | J6: =Cleaned_Prepared_Data!I6 -> 97.6 | K6: =Cleaned_Prepared_Data!K6 -> 1 | L6: =Cleaned_Prepared_Data!L6 -> 4.2 | M6: =IF($D6="Airport",1,0) -> 0 | N6: =IF($D6="High Street",1,0) -> 1 | O6: =IF($D6="Mall",1,0) -> 0
A7: =Cleaned_Prepared_Data!A7 -> STR-1002 | B7: =Cleaned_Prepared_Data!P7 -> 2025-02 | C7: =Cleaned_Prepared_Data!C7 -> East | D7: =Cleaned_Prepared_Data!D7 -> High Street | E7: =Cleaned_Prepared_Data!M7 -> 761835.34 | F7: =Cleaned_Prepared_Data!E7 -> 64811.21 | G7: =Cleaned_Prepared_Data!F7 -> 9792 | H7: =Cleaned_Prepared_Data!G7 -> 0.112 | I7: =Cleaned_Prepared_Data!H7 -> 20 | J7: =Cleaned_Prepared_Data!I7 -> 84.2 | K7: =Cleaned_Prepared_Data!K7 -> 0 | L7: =Cleaned_Prepared_Data!L7 -> 4.2 | M7: =IF($D7="Airport",1,0) -> 0 | N7: =IF($D7="High Street",1,0) -> 1 | O7: =IF($D7="Mall",1,0) -> 0
A8: =Cleaned_Prepared_Data!A8 -> STR-1002 | B8: =Cleaned_Prepared_Data!P8 -> 2025-03 | C8: =Cleaned_Prepared_Data!C8 -> East | D8: =Cleaned_Prepared_Data!D8 -> High Street | E8: =Cleaned_Prepared_Data!M8 -> 806615.54 | F8: =Cleaned_Prepared_Data!E8 -> 46213.45 | G8: =Cleaned_Prepared_Data!F8 -> 10616 | H8: =Cleaned_Prepared_Data!G8 -> 0.122 | I8: =Cleaned_Prepared_Data!H8 -> 22 | J8: =Cleaned_Prepared_Data!I8 -> 85.2 | K8: =Cleaned_Prepared_Data!K8 -> 1 | L8: =Cleaned_Prepared_Data!L8 -> 4.1 | M8: =IF($D8="Airport",1,0) -> 0 | N8: =IF($D8="High Street",1,0) -> 1 | O8: =IF($D8="Mall",1,0) -> 0
A9: =Cleaned_Prepared_Data!A9 -> STR-1002 | B9: =Cleaned_Prepared_Data!P9 -> 2025-04 | C9: =Cleaned_Prepared_Data!C9 -> East | D9: =Cleaned_Prepared_Data!D9 -> High Street | E9: =Cleaned_Prepared_Data!M9 -> 850164.26 | F9: =Cleaned_Prepared_Data!E9 -> 68148.52 | G9: =Cleaned_Prepared_Data!F9 -> 8567 | H9: =Cleaned_Prepared_Data!G9 -> 0.127 | I9: =Cleaned_Prepared_Data!H9 -> 23 | J9: =Cleaned_Prepared_Data!I9 -> 95.6 | K9: =Cleaned_Prepared_Data!K9 -> 0 | L9: =Cleaned_Prepared_Data!L9 -> 3.9 | M9: =IF($D9="Airport",1,0) -> 0 | N9: =IF($D9="High Street",1,0) -> 1 | O9: =IF($D9="Mall",1,0) -> 0
A10: =Cleaned_Prepared_Data!A10 -> STR-1003 | B10: =Cleaned_Prepared_Data!P10 -> 2025-01 | C10: =Cleaned_Prepared_Data!C10 -> North | D10: =Cleaned_Prepared_Data!D10 -> Airport | E10: =Cleaned_Prepared_Data!M10 -> 930581.7 | F10: =Cleaned_Prepared_Data!E10 -> 71838.86 | G10: =Cleaned_Prepared_Data!F10 -> 10979 | H10: =Cleaned_Prepared_Data!G10 -> 0.215 | I10: =Cleaned_Prepared_Data!H10 -> 26 | J10: =Cleaned_Prepared_Data!I10 -> 88.6 | K10: =Cleaned_Prepared_Data!K10 -> 1 | L10: =Cleaned_Prepared_Data!L10 -> 3.8 | M10: =IF($D10="Airport",1,0) -> 1 | N10: =IF($D10="High Street",1,0) -> 0 | O10: =IF($D10="Mall",1,0) -> 0
A11: =Cleaned_Prepared_Data!A11 -> STR-1003 | B11: =Cleaned_Prepared_Data!P11 -> 2025-02 | C11: =Cleaned_Prepared_Data!C11 -> North | D11: =Cleaned_Prepared_Data!D11 -> Airport | E11: =Cleaned_Prepared_Data!M11 -> 779010.94 | F11: =Cleaned_Prepared_Data!E11 -> 68133.44 | G11: =Cleaned_Prepared_Data!F11 -> 9459 | H11: =Cleaned_Prepared_Data!G11 -> 0.22 | I11: =Cleaned_Prepared_Data!H11 -> 21 | J11: =Cleaned_Prepared_Data!I11 -> 85 | K11: =Cleaned_Prepared_Data!K11 -> 0 | L11: =Cleaned_Prepared_Data!L11 -> 4.2 | M11: =IF($D11="Airport",1,0) -> 1 | N11: =IF($D11="High Street",1,0) -> 0 | O11: =IF($D11="Mall",1,0) -> 0
A12: =Cleaned_Prepared_Data!A12 -> STR-1003 | B12: =Cleaned_Prepared_Data!P12 -> 2025-03 | C12: =Cleaned_Prepared_Data!C12 -> North | D12: =Cleaned_Prepared_Data!D12 -> Airport | E12: =Cleaned_Prepared_Data!M12 -> 723060.76 | F12: =Cleaned_Prepared_Data!E12 -> 34285.21 | G12: =Cleaned_Prepared_Data!F12 -> 9172 | H12: =Cleaned_Prepared_Data!G12 -> 0.213 | I12: =Cleaned_Prepared_Data!H12 -> 22 | J12: =Cleaned_Prepared_Data!I12 -> 88.3 | K12: =Cleaned_Prepared_Data!K12 -> 1 | L12: =Cleaned_Prepared_Data!L12 -> 3.8 | M12: =IF($D12="Airport",1,0) -> 1 | N12: =IF($D12="High Street",1,0) -> 0 | O12: =IF($D12="Mall",1,0) -> 0
A13: =Cleaned_Prepared_Data!A13 -> STR-1003 | B13: =Cleaned_Prepared_Data!P13 -> 2025-04 | C13: =Cleaned_Prepared_Data!C13 -> North | D13: =Cleaned_Prepared_Data!D13 -> Airport | E13: =Cleaned_Prepared_Data!M13 -> 910791.94 | F13: =Cleaned_Prepared_Data!E13 -> 67979.88 | G13: =Cleaned_Prepared_Data!F13 -> 11230 | H13: =Cleaned_Prepared_Data!G13 -> 0.002 | I13: =Cleaned_Prepared_Data!H13 -> 28 | J13: =Cleaned_Prepared_Data!I13 -> 85.3 | K13: =Cleaned_Prepared_Data!K13 -> 0 | L13: =Cleaned_Prepared_Data!L13 -> 3.8 | M13: =IF($D13="Airport",1,0) -> 1 | N13: =IF($D13="High Street",1,0) -> 0 | O13: =IF($D13="Mall",1,0) -> 0
... A321: =Cleaned_Prepared_Data!A321 -> STR-1080 | B321: =Cleaned_Prepared_Data!P321 -> 2025-04 | C321: =Cleaned_Prepared_Data!C321 -> East | D321: =Cleaned_Prepared_Data!D321 -> Residential | E321: =Cleaned_Prepared_Data!M321 -> 559660.84 | F321: =Cleaned_Prepared_Data!E321 -> 40553.11 | G321: =Cleaned_Prepared_Data!F321 -> 5317 | H321: =Cleaned_Prepared_Data!G321 -> 0.165 | I321: =Cleaned_Prepared_Data!H321 -> 17 | J321: =Cleaned_Prepared_Data!I321 -> 84.3 | K321: =Cleaned_Prepared_Data!K321 -> 0 | L321: =Cleaned_Prepared_Data!L321 -> 4.1 | M321: =IF($D321="Airport",1,0) -> 0 | N321: =IF($D321="High Street",1,0) -> 0 | O321: =IF($D321="Mall",1,0) -> 0

Sheet Simple_Reg_Marketing
A1: Simple Reg Marketing
A3: Metric | B3: Value
A4: Model | B4: Simple Regression - Marketing Spend
A5: Dependent Variable | B5: monthly_sales
A6: Independent Variables | B6: marketing_spend
A7: Observations | B7: 320
A8: R-squared | B8: 0.16724469
A9: Adjusted R-squared | B9: 0.16462596
A10: F-statistic p-value | B10: 2.4800615e-14
A12: Term | B12: Coefficient | C12: Std Error | D12: t Stat | E12: P-value
A13: const | B13: 560777.35 | C13: 15906.906 | D13: 35.253703 | E13: 0
A14: marketing_spend | B14: 2.129575 | C14: 0.266478 | D14: 7.99155 | E14: 0
A22: Excel formula checks
A23: Intercept | B23: =INTERCEPT(Cleaned_Prepared_Data!M:M,Cleaned_Prepared_Data!E:E) -> 560777.35
A24: Coefficient | B24: =SLOPE(Cleaned_Prepared_Data!M:M,Cleaned_Prepared_Data!E:E) -> 2.1295753
A25: R-squared | B25: =RSQ(Cleaned_Prepared_Data!M:M,Cleaned_Prepared_Data!E:E) -> 0.16724469
A26: Equation | B26: monthly_sales = Intercept + Coefficient × marketing_spend

Sheet Simple_Reg_Footfall
A1: Simple Reg Footfall
A3: Metric | B3: Value
A4: Model | B4: Simple Regression - Footfall
A5: Dependent Variable | B5: monthly_sales
A6: Independent Variables | B6: footfall
A7: Observations | B7: 320
A8: R-squared | B8: 0.73628534
A9: Adjusted R-squared | B9: 0.73545605
A10: F-statistic p-value | B10: 4.7503615e-94
A12: Term | B12: Coefficient | C12: Std Error | D12: t Stat | E12: P-value
A13: const | B13: 446410.58 | C13: 8407.7383 | D13: 53.095205 | E13: 0
A14: footfall | B14: 35.678031 | C14: 1.197378 | D14: 29.796791 | E14: 0
A22: Excel formula checks
A23: Intercept | B23: =INTERCEPT(Cleaned_Prepared_Data!M:M,Cleaned_Prepared_Data!F:F) -> 446410.58
A24: Coefficient | B24: =SLOPE(Cleaned_Prepared_Data!M:M,Cleaned_Prepared_Data!F:F) -> 35.678031
A25: R-squared | B25: =RSQ(Cleaned_Prepared_Data!M:M,Cleaned_Prepared_Data!F:F) -> 0.73628534
A26: Equation | B26: monthly_sales = Intercept + Coefficient × footfall

Sheet Multiple_Reg_Output
A1: Multiple Reg Output
A3: Metric | B3: Value
A4: Model | B4: Multiple Regression - Business Driver Model
A5: Dependent Variable | B5: monthly_sales
A6: Independent Variables | B6: marketing_spend, footfall, avg_discount_pct, staff_count, inventory_availability_pct, holiday_flag, customer_rating, store_type_Airport, store_type_High Street, store_type_Mall
A7: Observations | B7: 312
A8: R-squared | B8: 0.82562309
A9: Adjusted R-squared | B9: 0.81982984
A10: F-statistic p-value | B10: 7.4499178e-108
A12: Term | B12: Coefficient | C12: Std Error | D12: t Stat | E12: P-value
A13: const | B13: 55572.027 | C13: 49448.307 | D13: 1.123841 | E13: 0.261976
A14: marketing_spend | B14: 1.15651 | C14: 0.128019 | D14: 9.033895 | E14: 0
A15: footfall | B15: 28.413881 | C15: 2.498044 | D15: 11.374452 | E15: 0
A16: avg_discount_pct | B16: -65319.737 | C16: 36512.402 | D16: -1.788974 | E16: 0.074624
A17: staff_count | B17: 2824.3013 | C17: 1264.422 | D17: 2.23367 | E17: 0.026239
A18: inventory_availability_pct | B18: 3015.9378 | C18: 466.6566 | D18: 6.462863 | E18: 0
A19: holiday_flag | B19: 11926.542 | C19: 6618.4731 | D19: 1.802008 | E19: 0.072545
A20: customer_rating | B20: 13003.353 | C20: 4775.2369 | D20: 2.72308 | E20: 0.006845
A21: store_type_Airport | B21: 39203.528 | C21: 9420.4546 | D21: 4.161532 | E21: 4.1e-05
A22: store_type_High Street | B22: 17947.161 | C22: 6107.4081 | D22: 2.938589 | E22: 0.003552
A23: store_type_Mall | B23: 26987.471 | C23: 6718.3327 | D23: 4.016989 | E23: 7.5e-05
A26: Equation note
A27: Residential is excluded as reference category to avoid dummy variable trap.

Sheet Predictions_Residuals
A1: store_id | B1: month_year | C1: region | D1: store_type | E1: monthly_sales | F1: marketing_spend | G1: footfall | H1: avg_discount_pct | I1: staff_count | J1: inventory_availability_pct | K1: holiday_flag | L1: customer_rating | M1: store_type_airport | N1: store_type_high_street | O1: store_type_mall | P1: predicted_sales | Q1: residual | R1: abs_residual | S1: residual_type | U1: Term | V1: Coefficient
A2: =Dummy_Variables!A2 -> STR-1001 | B2: =Dummy_Variables!B2 -> 2025-01 | C2: =Dummy_Variables!C2 -> East | D2: =Dummy_Variables!D2 -> Residential | E2: =Dummy_Variables!E2 -> 658832.62 | F2: =Dummy_Variables!F2 -> 70389.11 | G2: =Dummy_Variables!G2 -> 8302 | H2: =Dummy_Variables!H2 -> 0.042 | ... O2: =Dummy_Variables!O2 -> 0 | P2: =_xlfn.SINGLE(_xlfn.XLOOKUP("Intercept", $U:$U, $V:$V)) + F2 * _xlfn.SINGLE(_xlfn.XLOOKUP("marketing_spend", $U:$U, $V:$V)) + G2 * _xlfn.SINGLE(_xlfn.XLOOKUP("footfall", $U:$U, $V:$V)) + H2 * _xlfn.SINGLE(_xlfn.XLOOKUP("avg_discount_pct", $U:$U, $V:$V)) + I2 * _xlfn.SINGLE(_xlfn.XLOOKUP("staff_count", $U:$U, $V:$V)) + J2 * _xlfn.SINGLE(_xlfn.XLOOKUP("inventory_availability_pct", $U:$U, $V:$V)) + K2 * _xlfn.SINGLE(_xlfn.XLOOKUP("holiday_flag", $U:$U, $V:$V)) + L2 * _xlfn.SINGLE(_xlfn.XLOOKUP("customer_rating", $U:$U, $V:$V)) + M2 * _xlfn.SINGLE(_xlfn.XLOOKUP("store_type_airport", $U:$U, $V:$V)) + N2 * _xlfn.SINGLE(_xlfn.XLOOKUP("store_type_high_street", $U:$U, $V:$V)) + O2 * _xlfn.SINGLE(_xlfn.XLOOKUP("store_type_mall", $U:$U, $V:$V)) -> 696571.78 | Q2: =E2-P2 -> -37739.157 | R2: =ABS(Q2) -> 37739.157 | S2: =IF(Q2>0,"Positive residual - actual above prediction",IF(Q2<0,"Negative residual - actual below prediction","No residual")) -> Negative residual - actual below prediction | U2: Intercept | V2: 55572.027
A3: =Dummy_Variables!A3 -> STR-1001 | B3: =Dummy_Variables!B3 -> 2025-02 | C3: =Dummy_Variables!C3 -> East | D3: =Dummy_Variables!D3 -> Residential | E3: =Dummy_Variables!E3 -> 634436 | F3: =Dummy_Variables!F3 -> 43827.89 | G3: =Dummy_Variables!G3 -> 8487 | H3: =Dummy_Variables!H3 -> 0.168 | ... O3: =Dummy_Variables!O3 -> 0 | P3: =_xlfn.SINGLE(_xlfn.XLOOKUP("Intercept", $U:$U, $V:$V)) + F3 * _xlfn.SINGLE(_xlfn.XLOOKUP("marketing_spend", $U:$U, $V:$V)) + G3 * _xlfn.SINGLE(_xlfn.XLOOKUP("footfall", $U:$U, $V:$V)) + H3 * _xlfn.SINGLE(_xlfn.XLOOKUP("avg_discount_pct", $U:$U, $V:$V)) + I3 * _xlfn.SINGLE(_xlfn.XLOOKUP("staff_count", $U:$U, $V:$V)) + J3 * _xlfn.SINGLE(_xlfn.XLOOKUP("inventory_availability_pct", $U:$U, $V:$V)) + K3 * _xlfn.SINGLE(_xlfn.XLOOKUP("holiday_flag", $U:$U, $V:$V)) + L3 * _xlfn.SINGLE(_xlfn.XLOOKUP("customer_rating", $U:$U, $V:$V)) + M3 * _xlfn.SINGLE(_xlfn.XLOOKUP("store_type_airport", $U:$U, $V:$V)) + N3 * _xlfn.SINGLE(_xlfn.XLOOKUP("store_type_high_street", $U:$U, $V:$V)) + O3 * _xlfn.SINGLE(_xlfn.XLOOKUP("store_type_mall", $U:$U, $V:$V)) -> 692347.8 | Q3: =E3-P3 -> -57911.804 | R3: =ABS(Q3) -> 57911.804 | S3: =IF(Q3>0,"Positive residual - actual above prediction",IF(Q3<0,"Negative residual - actual below prediction","No residual")) -> Negative residual - actual below prediction | U3: marketing_spend | V3: 1.1565105
A4: =Dummy_Variables!A4 -> STR-1001 | B4: =Dummy_Variables!B4 -> 2025-03 | C4: =Dummy_Variables!C4 -> East | D4: =Dummy_Variables!D4 -> Residential | E4: =Dummy_Variables!E4 -> 678722.06 | F4: =Dummy_Variables!F4 -> 59921.75 | G4: =Dummy_Variables!G4 -> 9113 | H4: =Dummy_Variables!H4 -> 0.133 | ... O4: =Dummy_Variables!O4 -> 0 | P4: =_xlfn.SINGLE(_xlfn.XLOOKUP("Intercept", $U:$U, $V:$V)) + F4 * _xlfn.SINGLE(_xlfn.XLOOKUP("marketing_spend", $U:$U, $V:$V)) + G4 * _xlfn.SINGLE(_xlfn.XLOOKUP("footfall", $U:$U, $V:$V)) + H4 * _xlfn.SINGLE(_xlfn.XLOOKUP("avg_discount_pct", $U:$U, $V:$V)) + I4 * _xlfn.SINGLE(_xlfn.XLOOKUP("staff_count", $U:$U, $V:$V)) + J4 * _xlfn.SINGLE(_xlfn.XLOOKUP("inventory_availability_pct", $U:$U, $V:$V)) + K4 * _xlfn.SINGLE(_xlfn.XLOOKUP("holiday_flag", $U:$U, $V:$V)) + L4 * _xlfn.SINGLE(_xlfn.XLOOKUP("customer_rating", $U:$U, $V:$V)) + M4 * _xlfn.SINGLE(_xlfn.XLOOKUP("store_type_airport", $U:$U, $V:$V)) + N4 * _xlfn.SINGLE(_xlfn.XLOOKUP("store_type_high_street", $U:$U, $V:$V)) + O4 * _xlfn.SINGLE(_xlfn.XLOOKUP("store_type_mall", $U:$U, $V:$V)) -> 738619.62 | Q4: =E4-P4 -> -59897.556 | R4: =ABS(Q4) -> 59897.556 | S4: =IF(Q4>0,"Positive residual - actual above prediction",IF(Q4<0,"Negative residual - actual below prediction","No residual")) -> Negative residual - actual below prediction | U4: footfall | V4: 28.413881
A5: =Dummy_Variables!A5 -> STR-1001 | B5: =Dummy_Variables!B5 -> 2025-04 | C5: =Dummy_Variables!C5 -> East | D5: =Dummy_Variables!D5 -> Residential | E5: =Dummy_Variables!E5 -> 658920.3 | F5: =Dummy_Variables!F5 -> 56856.63 | G5: =Dummy_Variables!G5 -> 9431 | H5: =Dummy_Variables!H5 -> 0.142 | ... O5: =Dummy_Variables!O5 -> 0 | P5: =_xlfn.SINGLE(_xlfn.XLOOKUP("Intercept", $U:$U, $V:$V)) + F5 * _xlfn.SINGLE(_xlfn.XLOOKUP("marketing_spend", $U:$U, $V:$V)) + G5 * _xlfn.SINGLE(_xlfn.XLOOKUP("footfall", $U:$U, $V:$V)) + H5 * _xlfn.SINGLE(_xlfn.XLOOKUP("avg_discount_pct", $U:$U, $V:$V)) + I5 * _xlfn.SINGLE(_xlfn.XLOOKUP("staff_count", $U:$U, $V:$V)) + J5 * _xlfn.SINGLE(_xlfn.XLOOKUP("inventory_availability_pct", $U:$U, $V:$V)) + K5 * _xlfn.SINGLE(_xlfn.XLOOKUP("holiday_flag", $U:$U, $V:$V)) + L5 * _xlfn.SINGLE(_xlfn.XLOOKUP("customer_rating", $U:$U, $V:$V)) + M5 * _xlfn.SINGLE(_xlfn.XLOOKUP("store_type_airport", $U:$U, $V:$V)) + N5 * _xlfn.SINGLE(_xlfn.XLOOKUP("store_type_high_street", $U:$U, $V:$V)) + O5 * _xlfn.SINGLE(_xlfn.XLOOKUP("store_type_mall", $U:$U, $V:$V)) -> 751278.55 | Q5: =E5-P5 -> -92358.252 | R5: =ABS(Q5) -> 92358.252 | S5: =IF(Q5>0,"Positive residual - actual above prediction",IF(Q5<0,"Negative residual - actual below prediction","No residual")) -> Negative residual - actual below prediction | U5: avg_discount_pct | V5: -65319.737
A6: =Dummy_Variables!A6 -> STR-1002 | B6: =Dummy_Variables!B6 -> 2025-01 | C6: =Dummy_Variables!C6 -> East | D6: =Dummy_Variables!D6 -> High Street | E6: =Dummy_Variables!E6 -> 741341.44 | F6: =Dummy_Variables!F6 -> 48412.64 | G6: =Dummy_Variables!G6 -> 9545 | H6: =Dummy_Variables!H6 -> 0.231 | ... O6: =Dummy_Variables!O6 -> 0 | P6: =_xlfn.SINGLE(_xlfn.XLOOKUP("Intercept", $U:$U, $V:$V)) + F6 * _xlfn.SINGLE(_xlfn.XLOOKUP("marketing_spend", $U:$U, $V:$V)) + G6 * _xlfn.SINGLE(_xlfn.XLOOKUP("footfall", $U:$U, $V:$V)) + H6 * _xlfn.SINGLE(_xlfn.XLOOKUP("avg_discount_pct", $U:$U, $V:$V)) + I6 * _xlfn.SINGLE(_xlfn.XLOOKUP("staff_count", $U:$U, $V:$V)) + J6 * _xlfn.SINGLE(_xlfn.XLOOKUP("inventory_availability_pct", $U:$U, $V:$V)) + K6 * _xlfn.SINGLE(_xlfn.XLOOKUP("holiday_flag", $U:$U, $V:$V)) + L6 * _xlfn.SINGLE(_xlfn.XLOOKUP("customer_rating", $U:$U, $V:$V)) + M6 * _xlfn.SINGLE(_xlfn.XLOOKUP("store_type_airport", $U:$U, $V:$V)) + N6 * _xlfn.SINGLE(_xlfn.XLOOKUP("store_type_high_street", $U:$U, $V:$V)) + O6 * _xlfn.SINGLE(_xlfn.XLOOKUP("store_type_mall", $U:$U, $V:$V)) -> 805837.03 | Q6: =E6-P6 -> -64495.592 | R6: =ABS(Q6) -> 64495.592 | S6: =IF(Q6>0,"Positive residual - actual above prediction",IF(Q6<0,"Negative residual - actual below prediction","No residual")) -> Negative residual - actual below prediction | U6: staff_count | V6: 2824.3013
A7: =Dummy_Variables!A7 -> STR-1002 | B7: =Dummy_Variables!B7 -> 2025-02 | C7: =Dummy_Variables!C7 -> East | D7: =Dummy_Variables!D7 -> High Street | E7: =Dummy_Variables!E7 -> 761835.34 | F7: =Dummy_Variables!F7 -> 64811.21 | G7: =Dummy_Variables!G7 -> 9792 | H7: =Dummy_Variables!H7 -> 0.112 | ... O7: =Dummy_Variables!O7 -> 0 | P7: =_xlfn.SINGLE(_xlfn.XLOOKUP("Intercept", $U:$U, $V:$V)) + F7 * _xlfn.SINGLE(_xlfn.XLOOKUP("marketing_spend", $U:$U, $V:$V)) + G7 * _xlfn.SINGLE(_xlfn.XLOOKUP("footfall", $U:$U, $V:$V)) + H7 * _xlfn.SINGLE(_xlfn.XLOOKUP("avg_discount_pct", $U:$U, $V:$V)) + I7 * _xlfn.SINGLE(_xlfn.XLOOKUP("staff_count", $U:$U, $V:$V)) + J7 * _xlfn.SINGLE(_xlfn.XLOOKUP("inventory_availability_pct", $U:$U, $V:$V)) + K7 * _xlfn.SINGLE(_xlfn.XLOOKUP("holiday_flag", $U:$U, $V:$V)) + L7 * _xlfn.SINGLE(_xlfn.XLOOKUP("customer_rating", $U:$U, $V:$V)) + M7 * _xlfn.SINGLE(_xlfn.XLOOKUP("store_type_airport", $U:$U, $V:$V)) + N7 * _xlfn.SINGLE(_xlfn.XLOOKUP("store_type_high_street", $U:$U, $V:$V)) + O7 * _xlfn.SINGLE(_xlfn.XLOOKUP("store_type_mall", $U:$U, $V:$V)) -> 784429.02 | Q7: =E7-P7 -> -22593.678 | R7: =ABS(Q7) -> 22593.678 | S7: =IF(Q7>0,"Positive residual - actual above prediction",IF(Q7<0,"Negative residual - actual below prediction","No residual")) -> Negative residual - actual below prediction | U7: inventory_availability_pct | V7: 3015.9378
A8: =Dummy_Variables!A8 -> STR-1002 | B8: =Dummy_Variables!B8 -> 2025-03 | C8: =Dummy_Variables!C8 -> East | D8: =Dummy_Variables!D8 -> High Street | E8: =Dummy_Variables!E8 -> 806615.54 | F8: =Dummy_Variables!F8 -> 46213.45 | G8: =Dummy_Variables!G8 -> 10616 | H8: =Dummy_Variables!H8 -> 0.122 | ... O8: =Dummy_Variables!O8 -> 0 | P8: =_xlfn.SINGLE(_xlfn.XLOOKUP("Intercept", $U:$U, $V:$V)) + F8 * _xlfn.SINGLE(_xlfn.XLOOKUP("marketing_spend", $U:$U, $V:$V)) + G8 * _xlfn.SINGLE(_xlfn.XLOOKUP("footfall", $U:$U, $V:$V)) + H8 * _xlfn.SINGLE(_xlfn.XLOOKUP("avg_discount_pct", $U:$U, $V:$V)) + I8 * _xlfn.SINGLE(_xlfn.XLOOKUP("staff_count", $U:$U, $V:$V)) + J8 * _xlfn.SINGLE(_xlfn.XLOOKUP("inventory_availability_pct", $U:$U, $V:$V)) + K8 * _xlfn.SINGLE(_xlfn.XLOOKUP("holiday_flag", $U:$U, $V:$V)) + L8 * _xlfn.SINGLE(_xlfn.XLOOKUP("customer_rating", $U:$U, $V:$V)) + M8 * _xlfn.SINGLE(_xlfn.XLOOKUP("store_type_airport", $U:$U, $V:$V)) + N8 * _xlfn.SINGLE(_xlfn.XLOOKUP("store_type_high_street", $U:$U, $V:$V)) + O8 * _xlfn.SINGLE(_xlfn.XLOOKUP("store_type_mall", $U:$U, $V:$V)) -> 804971.1 | Q8: =E8-P8 -> 1644.4393 | R8: =ABS(Q8) -> 1644.4393 | S8: =IF(Q8>0,"Positive residual - actual above prediction",IF(Q8<0,"Negative residual - actual below prediction","No residual")) -> Positive residual - actual above prediction | U8: holiday_flag | V8: 11926.542
A9: =Dummy_Variables!A9 -> STR-1002 | B9: =Dummy_Variables!B9 -> 2025-04 | C9: =Dummy_Variables!C9 -> East | D9: =Dummy_Variables!D9 -> High Street | E9: =Dummy_Variables!E9 -> 850164.26 | F9: =Dummy_Variables!F9 -> 68148.52 | G9: =Dummy_Variables!G9 -> 8567 | H9: =Dummy_Variables!H9 -> 0.127 | ... O9: =Dummy_Variables!O9 -> 0 | P9: =_xlfn.SINGLE(_xlfn.XLOOKUP("Intercept", $U:$U, $V:$V)) + F9 * _xlfn.SINGLE(_xlfn.XLOOKUP("marketing_spend", $U:$U, $V:$V)) + G9 * _xlfn.SINGLE(_xlfn.XLOOKUP("footfall", $U:$U, $V:$V)) + H9 * _xlfn.SINGLE(_xlfn.XLOOKUP("avg_discount_pct", $U:$U, $V:$V)) + I9 * _xlfn.SINGLE(_xlfn.XLOOKUP("staff_count", $U:$U, $V:$V)) + J9 * _xlfn.SINGLE(_xlfn.XLOOKUP("inventory_availability_pct", $U:$U, $V:$V)) + K9 * _xlfn.SINGLE(_xlfn.XLOOKUP("holiday_flag", $U:$U, $V:$V)) + L9 * _xlfn.SINGLE(_xlfn.XLOOKUP("customer_rating", $U:$U, $V:$V)) + M9 * _xlfn.SINGLE(_xlfn.XLOOKUP("store_type_airport", $U:$U, $V:$V)) + N9 * _xlfn.SINGLE(_xlfn.XLOOKUP("store_type_high_street", $U:$U, $V:$V)) + O9 * _xlfn.SINGLE(_xlfn.XLOOKUP("store_type_mall", $U:$U, $V:$V)) -> 791455.44 | Q9: =E9-P9 -> 58708.819 | R9: =ABS(Q9) -> 58708.819 | S9: =IF(Q9>0,"Positive residual - actual above prediction",IF(Q9<0,"Negative residual - actual below prediction","No residual")) -> Positive residual - actual above prediction | U9: customer_rating | V9: 13003.353
A10: =Dummy_Variables!A10 -> STR-1003 | B10: =Dummy_Variables!B10 -> 2025-01 | C10: =Dummy_Variables!C10 -> North | D10: =Dummy_Variables!D10 -> Airport | E10: =Dummy_Variables!E10 -> 930581.7 | F10: =Dummy_Variables!F10 -> 71838.86 | G10: =Dummy_Variables!G10 -> 10979 | H10: =Dummy_Variables!H10 -> 0.215 | ... O10: =Dummy_Variables!O10 -> 0 | P10: =_xlfn.SINGLE(_xlfn.XLOOKUP("Intercept", $U:$U, $V:$V)) + F10 * _xlfn.SINGLE(_xlfn.XLOOKUP("marketing_spend", $U:$U, $V:$V)) + G10 * _xlfn.SINGLE(_xlfn.XLOOKUP("footfall", $U:$U, $V:$V)) + H10 * _xlfn.SINGLE(_xlfn.XLOOKUP("avg_discount_pct", $U:$U, $V:$V)) + I10 * _xlfn.SINGLE(_xlfn.XLOOKUP("staff_count", $U:$U, $V:$V)) + J10 * _xlfn.SINGLE(_xlfn.XLOOKUP("inventory_availability_pct", $U:$U, $V:$V)) + K10 * _xlfn.SINGLE(_xlfn.XLOOKUP("holiday_flag", $U:$U, $V:$V)) + L10 * _xlfn.SINGLE(_xlfn.XLOOKUP("customer_rating", $U:$U, $V:$V)) + M10 * _xlfn.SINGLE(_xlfn.XLOOKUP("store_type_airport", $U:$U, $V:$V)) + N10 * _xlfn.SINGLE(_xlfn.XLOOKUP("store_type_high_street", $U:$U, $V:$V)) + O10 * _xlfn.SINGLE(_xlfn.XLOOKUP("store_type_mall", $U:$U, $V:$V)) -> 877753.41 | Q10: =E10-P10 -> 52828.287 | R10: =ABS(Q10) -> 52828.287 | S10: =IF(Q10>0,"Positive residual - actual above prediction",IF(Q10<0,"Negative residual - actual below prediction","No residual")) -> Positive residual - actual above prediction | U10: store_type_airport | V10: 39203.528
A11: =Dummy_Variables!A11 -> STR-1003 | B11: =Dummy_Variables!B11 -> 2025-02 | C11: =Dummy_Variables!C11 -> North | D11: =Dummy_Variables!D11 -> Airport | E11: =Dummy_Variables!E11 -> 779010.94 | F11: =Dummy_Variables!F11 -> 68133.44 | G11: =Dummy_Variables!G11 -> 9459 | H11: =Dummy_Variables!H11 -> 0.22 | ... O11: =Dummy_Variables!O11 -> 0 | P11: =_xlfn.SINGLE(_xlfn.XLOOKUP("Intercept", $U:$U, $V:$V)) + F11 * _xlfn.SINGLE(_xlfn.XLOOKUP("marketing_spend", $U:$U, $V:$V)) + G11 * _xlfn.SINGLE(_xlfn.XLOOKUP("footfall", $U:$U, $V:$V)) + H11 * _xlfn.SINGLE(_xlfn.XLOOKUP("avg_discount_pct", $U:$U, $V:$V)) + I11 * _xlfn.SINGLE(_xlfn.XLOOKUP("staff_count", $U:$U, $V:$V)) + J11 * _xlfn.SINGLE(_xlfn.XLOOKUP("inventory_availability_pct", $U:$U, $V:$V)) + K11 * _xlfn.SINGLE(_xlfn.XLOOKUP("holiday_flag", $U:$U, $V:$V)) + L11 * _xlfn.SINGLE(_xlfn.XLOOKUP("customer_rating", $U:$U, $V:$V)) + M11 * _xlfn.SINGLE(_xlfn.XLOOKUP("store_type_airport", $U:$U, $V:$V)) + N11 * _xlfn.SINGLE(_xlfn.XLOOKUP("store_type_high_street", $U:$U, $V:$V)) + O11 * _xlfn.SINGLE(_xlfn.XLOOKUP("store_type_mall", $U:$U, $V:$V)) -> 798248.28 | Q11: =E11-P11 -> -19237.336 | R11: =ABS(Q11) -> 19237.336 | S11: =IF(Q11>0,"Positive residual - actual above prediction",IF(Q11<0,"Negative residual - actual below prediction","No residual")) -> Negative residual - actual below prediction | U11: store_type_high_street | V11: 17947.161
A12: =Dummy_Variables!A12 -> STR-1003 | B12: =Dummy_Variables!B12 -> 2025-03 | C12: =Dummy_Variables!C12 -> North | D12: =Dummy_Variables!D12 -> Airport | E12: =Dummy_Variables!E12 -> 723060.76 | F12: =Dummy_Variables!F12 -> 34285.21 | G12: =Dummy_Variables!G12 -> 9172 | H12: =Dummy_Variables!H12 -> 0.213 | ... O12: =Dummy_Variables!O12 -> 0 | P12: =_xlfn.SINGLE(_xlfn.XLOOKUP("Intercept", $U:$U, $V:$V)) + F12 * _xlfn.SINGLE(_xlfn.XLOOKUP("marketing_spend", $U:$U, $V:$V)) + G12 * _xlfn.SINGLE(_xlfn.XLOOKUP("footfall", $U:$U, $V:$V)) + H12 * _xlfn.SINGLE(_xlfn.XLOOKUP("avg_discount_pct", $U:$U, $V:$V)) + I12 * _xlfn.SINGLE(_xlfn.XLOOKUP("staff_count", $U:$U, $V:$V)) + J12 * _xlfn.SINGLE(_xlfn.XLOOKUP("inventory_availability_pct", $U:$U, $V:$V)) + K12 * _xlfn.SINGLE(_xlfn.XLOOKUP("holiday_flag", $U:$U, $V:$V)) + L12 * _xlfn.SINGLE(_xlfn.XLOOKUP("customer_rating", $U:$U, $V:$V)) + M12 * _xlfn.SINGLE(_xlfn.XLOOKUP("store_type_airport", $U:$U, $V:$V)) + N12 * _xlfn.SINGLE(_xlfn.XLOOKUP("store_type_high_street", $U:$U, $V:$V)) + O12 * _xlfn.SINGLE(_xlfn.XLOOKUP("store_type_mall", $U:$U, $V:$V)) -> 770906.99 | Q12: =E12-P12 -> -47846.234 | R12: =ABS(Q12) -> 47846.234 | S12: =IF(Q12>0,"Positive residual - actual above prediction",IF(Q12<0,"Negative residual - actual below prediction","No residual")) -> Negative residual - actual below prediction | U12: store_type_mall | V12: 26987.471
A13: =Dummy_Variables!A13 -> STR-1003 | B13: =Dummy_Variables!B13 -> 2025-04 | C13: =Dummy_Variables!C13 -> North | D13: =Dummy_Variables!D13 -> Airport | E13: =Dummy_Variables!E13 -> 910791.94 | F13: =Dummy_Variables!F13 -> 67979.88 | G13: =Dummy_Variables!G13 -> 11230 | H13: =Dummy_Variables!H13 -> 0.002 | ... O13: =Dummy_Variables!O13 -> 0 | P13: =_xlfn.SINGLE(_xlfn.XLOOKUP("Intercept", $U:$U, $V:$V)) + F13 * _xlfn.SINGLE(_xlfn.XLOOKUP("marketing_spend", $U:$U, $V:$V)) + G13 * _xlfn.SINGLE(_xlfn.XLOOKUP("footfall", $U:$U, $V:$V)) + H13 * _xlfn.SINGLE(_xlfn.XLOOKUP("avg_discount_pct", $U:$U, $V:$V)) + I13 * _xlfn.SINGLE(_xlfn.XLOOKUP("staff_count", $U:$U, $V:$V)) + J13 * _xlfn.SINGLE(_xlfn.XLOOKUP("inventory_availability_pct", $U:$U, $V:$V)) + K13 * _xlfn.SINGLE(_xlfn.XLOOKUP("holiday_flag", $U:$U, $V:$V)) + L13 * _xlfn.SINGLE(_xlfn.XLOOKUP("customer_rating", $U:$U, $V:$V)) + M13 * _xlfn.SINGLE(_xlfn.XLOOKUP("store_type_airport", $U:$U, $V:$V)) + N13 * _xlfn.SINGLE(_xlfn.XLOOKUP("store_type_high_street", $U:$U, $V:$V)) + O13 * _xlfn.SINGLE(_xlfn.XLOOKUP("store_type_mall", $U:$U, $V:$V)) -> 878104.92 | Q13: =E13-P13 -> 32687.023 | R13: =ABS(Q13) -> 32687.023 | S13: =IF(Q13>0,"Positive residual - actual above prediction",IF(Q13<0,"Negative residual - actual below prediction","No residual")) -> Positive residual - actual above prediction
A14: =Dummy_Variables!A14 -> STR-1004 | B14: =Dummy_Variables!B14 -> 2025-01 | C14: =Dummy_Variables!C14 -> East | D14: =Dummy_Variables!D14 -> Residential | E14: =Dummy_Variables!E14 -> 922168.6 | F14: =Dummy_Variables!F14 -> 71828.26 | G14: =Dummy_Variables!G14 -> 12775 | H14: =Dummy_Variables!H14 -> 0.116 | ... O14: =Dummy_Variables!O14 -> 0 | P14: =_xlfn.SINGLE(_xlfn.XLOOKUP("Intercept", $U:$U, $V:$V)) + F14 * _xlfn.SINGLE(_xlfn.XLOOKUP("marketing_spend", $U:$U, $V:$V)) + G14 * _xlfn.SINGLE(_xlfn.XLOOKUP("footfall", $U:$U, $V:$V)) + H14 * _xlfn.SINGLE(_xlfn.XLOOKUP("avg_discount_pct", $U:$U, $V:$V)) + I14 * _xlfn.SINGLE(_xlfn.XLOOKUP("staff_count", $U:$U, $V:$V)) + J14 * _xlfn.SINGLE(_xlfn.XLOOKUP("inventory_availability_pct", $U:$U, $V:$V)) + K14 * _xlfn.SINGLE(_xlfn.XLOOKUP("holiday_flag", $U:$U, $V:$V)) + L14 * _xlfn.SINGLE(_xlfn.XLOOKUP("customer_rating", $U:$U, $V:$V)) + M14 * _xlfn.SINGLE(_xlfn.XLOOKUP("store_type_airport", $U:$U, $V:$V)) + N14 * _xlfn.SINGLE(_xlfn.XLOOKUP("store_type_high_street", $U:$U, $V:$V)) + O14 * _xlfn.SINGLE(_xlfn.XLOOKUP("store_type_mall", $U:$U, $V:$V)) -> 891724.19 | Q14: =E14-P14 -> 30444.414 | R14: =ABS(Q14) -> 30444.414 | S14: =IF(Q14>0,"Positive residual - actual above prediction",IF(Q14<0,"Negative residual - actual below prediction","No residual")) -> Positive residual - actual above prediction
A15: =Dummy_Variables!A15 -> STR-1004 | B15: =Dummy_Variables!B15 -> 2025-02 | C15: =Dummy_Variables!C15 -> East | D15: =Dummy_Variables!D15 -> Residential | E15: =Dummy_Variables!E15 -> 726606.28 | F15: =Dummy_Variables!F15 -> 55716.82 | G15: =Dummy_Variables!G15 -> 10054 | H15: =Dummy_Variables!H15 -> 0.146 | ... O15: =Dummy_Variables!O15 -> 0 | P15: =_xlfn.SINGLE(_xlfn.XLOOKUP("Intercept", $U:$U, $V:$V)) + F15 * _xlfn.SINGLE(_xlfn.XLOOKUP("marketing_spend", $U:$U, $V:$V)) + G15 * _xlfn.SINGLE(_xlfn.XLOOKUP("footfall", $U:$U, $V:$V)) + H15 * _xlfn.SINGLE(_xlfn.XLOOKUP("avg_discount_pct", $U:$U, $V:$V)) + I15 * _xlfn.SINGLE(_xlfn.XLOOKUP("staff_count", $U:$U, $V:$V)) + J15 * _xlfn.SINGLE(_xlfn.XLOOKUP("inventory_availability_pct", $U:$U, $V:$V)) + K15 * _xlfn.SINGLE(_xlfn.XLOOKUP("holiday_flag", $U:$U, $V:$V)) + L15 * _xlfn.SINGLE(_xlfn.XLOOKUP("customer_rating", $U:$U, $V:$V)) + M15 * _xlfn.SINGLE(_xlfn.XLOOKUP("store_type_airport", $U:$U, $V:$V)) + N15 * _xlfn.SINGLE(_xlfn.XLOOKUP("store_type_high_street", $U:$U, $V:$V)) + O15 * _xlfn.SINGLE(_xlfn.XLOOKUP("store_type_mall", $U:$U, $V:$V)) -> 775896.36 | Q15: =E15-P15 -> -49290.082 | R15: =ABS(Q15) -> 49290.082 | S15: =IF(Q15>0,"Positive residual - actual above prediction",IF(Q15<0,"Negative residual - actual below prediction","No residual")) -> Negative residual - actual below prediction
A16: =Dummy_Variables!A16 -> STR-1004 | B16: =Dummy_Variables!B16 -> 2025-03 | C16: =Dummy_Variables!C16 -> East | D16: =Dummy_Variables!D16 -> Residential | E16: =Dummy_Variables!E16 -> 746501.09 | F16: =Dummy_Variables!F16 -> 59909.51 | G16: =Dummy_Variables!G16 -> 8895 | H16: =Dummy_Variables!H16 -> 0.228 | ... O16: =Dummy_Variables!O16 -> 0 | P16: =_xlfn.SINGLE(_xlfn.XLOOKUP("Intercept", $U:$U, $V:$V)) + F16 * _xlfn.SINGLE(_xlfn.XLOOKUP("marketing_spend", $U:$U, $V:$V)) + G16 * _xlfn.SINGLE(_xlfn.XLOOKUP("footfall", $U:$U, $V:$V)) + H16 * _xlfn.SINGLE(_xlfn.XLOOKUP("avg_discount_pct", $U:$U, $V:$V)) + I16 * _xlfn.SINGLE(_xlfn.XLOOKUP("staff_count", $U:$U, $V:$V)) + J16 * _xlfn.SINGLE(_xlfn.XLOOKUP("inventory_availability_pct", $U:$U, $V:$V)) + K16 * _xlfn.SINGLE(_xlfn.XLOOKUP("holiday_flag", $U:$U, $V:$V)) + L16 * _xlfn.SINGLE(_xlfn.XLOOKUP("customer_rating", $U:$U, $V:$V)) + M16 * _xlfn.SINGLE(_xlfn.XLOOKUP("store_type_airport", $U:$U, $V:$V)) + N16 * _xlfn.SINGLE(_xlfn.XLOOKUP("store_type_high_street", $U:$U, $V:$V)) + O16 * _xlfn.SINGLE(_xlfn.XLOOKUP("store_type_mall", $U:$U, $V:$V)) -> 751395.2 | Q16: =E16-P16 -> -4894.1121 | R16: =ABS(Q16) -> 4894.1121 | S16: =IF(Q16>0,"Positive residual - actual above prediction",IF(Q16<0,"Negative residual - actual below prediction","No residual")) -> Negative residual - actual below prediction
A17: =Dummy_Variables!A17 -> STR-1004 | B17: =Dummy_Variables!B17 -> 2025-04 | C17: =Dummy_Variables!C17 -> East | D17: =Dummy_Variables!D17 -> Residential | E17: =Dummy_Variables!E17 -> 834017.02 | F17: =Dummy_Variables!F17 -> 75305.71 | G17: =Dummy_Variables!G17 -> 10940 | H17: =Dummy_Variables!H17 -> 0.006 | ... O17: =Dummy_Variables!O17 -> 0 | P17: =_xlfn.SINGLE(_xlfn.XLOOKUP("Intercept", $U:$U, $V:$V)) + F17 * _xlfn.SINGLE(_xlfn.XLOOKUP("marketing_spend", $U:$U, $V:$V)) + G17 * _xlfn.SINGLE(_xlfn.XLOOKUP("footfall", $U:$U, $V:$V)) + H17 * _xlfn.SINGLE(_xlfn.XLOOKUP("avg_discount_pct", $U:$U, $V:$V)) + I17 * _xlfn.SINGLE(_xlfn.XLOOKUP("staff_count", $U:$U, $V:$V)) + J17 * _xlfn.SINGLE(_xlfn.XLOOKUP("inventory_availability_pct", $U:$U, $V:$V)) + K17 * _xlfn.SINGLE(_xlfn.XLOOKUP("holiday_flag", $U:$U, $V:$V)) + L17 * _xlfn.SINGLE(_xlfn.XLOOKUP("customer_rating", $U:$U, $V:$V)) + M17 * _xlfn.SINGLE(_xlfn.XLOOKUP("store_type_airport", $U:$U, $V:$V)) + N17 * _xlfn.SINGLE(_xlfn.XLOOKUP("store_type_high_street", $U:$U, $V:$V)) + O17 * _xlfn.SINGLE(_xlfn.XLOOKUP("store_type_mall", $U:$U, $V:$V)) -> 815785.98 | Q17: =E17-P17 -> 18231.044 | R17: =ABS(Q17) -> 18231.044 | S17: =IF(Q17>0,"Positive residual - actual above prediction",IF(Q17<0,"Negative residual - actual below prediction","No residual")) -> Positive residual - actual above prediction
A18: =Dummy_Variables!A18 -> STR-1005 | B18: =Dummy_Variables!B18 -> 2025-01 | C18: =Dummy_Variables!C18 -> South | D18: =Dummy_Variables!D18 -> Residential | E18: =Dummy_Variables!E18 -> 666152.52 | F18: =Dummy_Variables!F18 -> 48804.22 | G18: =Dummy_Variables!G18 -> 7057 | H18: =Dummy_Variables!H18 -> 0.005 | ... O18: =Dummy_Variables!O18 -> 0 | P18: =_xlfn.SINGLE(_xlfn.XLOOKUP("Intercept", $U:$U, $V:$V)) + F18 * _xlfn.SINGLE(_xlfn.XLOOKUP("marketing_spend", $U:$U, $V:$V)) + G18 * _xlfn.SINGLE(_xlfn.XLOOKUP("footfall", $U:$U, $V:$V)) + H18 * _xlfn.SINGLE(_xlfn.XLOOKUP("avg_discount_pct", $U:$U, $V:$V)) + I18 * _xlfn.SINGLE(_xlfn.XLOOKUP("staff_count", $U:$U, $V:$V)) + J18 * _xlfn.SINGLE(_xlfn.XLOOKUP("inventory_availability_pct", $U:$U, $V:$V)) + K18 * _xlfn.SINGLE(_xlfn.XLOOKUP("holiday_flag", $U:$U, $V:$V)) + L18 * _xlfn.SINGLE(_xlfn.XLOOKUP("customer_rating", $U:$U, $V:$V)) + M18 * _xlfn.SINGLE(_xlfn.XLOOKUP("store_type_airport", $U:$U, $V:$V)) + N18 * _xlfn.SINGLE(_xlfn.XLOOKUP("store_type_high_street", $U:$U, $V:$V)) + O18 * _xlfn.SINGLE(_xlfn.XLOOKUP("store_type_mall", $U:$U, $V:$V)) -> 667179.45 | Q18: =E18-P18 -> -1026.9323 | R18: =ABS(Q18) -> 1026.9323 | S18: =IF(Q18>0,"Positive residual - actual above prediction",IF(Q18<0,"Negative residual - actual below prediction","No residual")) -> Negative residual - actual below prediction
A19: =Dummy_Variables!A19 -> STR-1005 | B19: =Dummy_Variables!B19 -> 2025-02 | C19: =Dummy_Variables!C19 -> South | D19: =Dummy_Variables!D19 -> Residential | E19: =Dummy_Variables!E19 -> 573155.19 | F19: =Dummy_Variables!F19 -> 59117.9 | G19: =Dummy_Variables!G19 -> 4263 | H19: =Dummy_Variables!H19 -> 0.119 | ... O19: =Dummy_Variables!O19 -> 0 | P19: =_xlfn.SINGLE(_xlfn.XLOOKUP("Intercept", $U:$U, $V:$V)) + F19 * _xlfn.SINGLE(_xlfn.XLOOKUP("marketing_spend", $U:$U, $V:$V)) + G19 * _xlfn.SINGLE(_xlfn.XLOOKUP("footfall", $U:$U, $V:$V)) + H19 * _xlfn.SINGLE(_xlfn.XLOOKUP("avg_discount_pct", $U:$U, $V:$V)) + I19 * _xlfn.SINGLE(_xlfn.XLOOKUP("staff_count", $U:$U, $V:$V)) + J19 * _xlfn.SINGLE(_xlfn.XLOOKUP("inventory_availability_pct", $U:$U, $V:$V)) + K19 * _xlfn.SINGLE(_xlfn.XLOOKUP("holiday_flag", $U:$U, $V:$V)) + L19 * _xlfn.SINGLE(_xlfn.XLOOKUP("customer_rating", $U:$U, $V:$V)) + M19 * _xlfn.SINGLE(_xlfn.XLOOKUP("store_type_airport", $U:$U, $V:$V)) + N19 * _xlfn.SINGLE(_xlfn.XLOOKUP("store_type_high_street", $U:$U, $V:$V)) + O19 * _xlfn.SINGLE(_xlfn.XLOOKUP("store_type_mall", $U:$U, $V:$V)) -> 573724.76 | Q19: =E19-P19 -> -569.57163 | R19: =ABS(Q19) -> 569.57163 | S19: =IF(Q19>0,"Positive residual - actual above prediction",IF(Q19<0,"Negative residual - actual below prediction","No residual")) -> Negative residual - actual below prediction
